<mujoco>
  <compiler angle="degree" coordinate="local" inertiafromgeom="true" />
  <option integrator="RK4" timestep="0.01" />
  <default>
    <joint armature="1" damping="1" limited="true" />
    <geom conaffinity="0" condim="3.0" density="5.0" friction="1 0.5 0.5" margin="0.01" rgba="0.4 0.6 1 1" />
  </default>
  <visual>
    <quality shadowsize="16384" />
    <map shadowclip="10" />
  </visual>
  <asset>
    <texture builtin="gradient" height="100" rgb1="1 1 1" rgb2="0.2 0.2 0.2" type="skybox" width="100" />
    <texture builtin="flat" height="1278" mark="cross" markrgb="1 1 1" name="texgeom" random="0.01" rgb1="0.8 0.6 0.4" rgb2="0.8 0.6 0.4" type="cube" width="127" />
    <texture builtin="checker" height="100" name="texplane" rgb1="0 0 0" rgb2="0.6 0.6 0.6" type="2d" width="100" />
    <material name="MatPlane" reflectance="0.5" shininess="1" specular="1" texrepeat="1 1" texture="texplane" />
    <material name="geom" texture="texgeom" texuniform="true" />
  </asset>
  <worldbody>
    <light cutoff="1" diffuse="1 1 1" dir="-0 0 -1.3" directional="true" exponent="1" pos="0 0 1.3" specular=".1 .1 .1" />
    <geom conaffinity="1" condim="3" material="MatPlane" name="floor" pos="0 0 0" rgba="1 1 1 1" size="0 0 10" type="plane" />
    <body pos="0 0 0.5" name="torso">
      <camera mode="track" pos="0 -3 3" xyaxes="1 0 0 0 1 1" fovy="45" />
      <camera mode="trackcom" pos="0 -2 1" xyaxes="1 0 0 0 1 2" fovy="45" />
      <geom size="0.08" fromto="-0.18774897958671743 0 0 0.18774897958671743 0 0" type="capsule" />
      <joint armature="0" damping="0" limited="false" margin="0.01" pos="0 0 0" type="free" />
      <body pos="-0.08714060285991537 0 0">
        <joint name="leg:0 segment:0" limited="false" type="ball" />
        <geom conaffinity="1" fromto="0 0 0 -0.2954495352967472 0.25342047993037964 0" size="0.08" type="capsule" />
        <body pos="-0.2954495352967472 0.25342047993037964 0">
          <joint name="leg:0 segment:1" limited="true" range="0 -60" type="ball" />
          <geom conaffinity="1" fromto="0 0 0 0.39047617475525787 -0.2984492108318786 0" size="0.08" type="capsule" />
          <body pos="0.39047617475525787 -0.2984492108318786 0">
            <joint name="leg:0 segment:2" limited="false" type="ball" />
            <geom conaffinity="1" fromto="0 0 0 -0.3770284119230636 0.2997747955864969 0" size="0.08" type="capsule" />
          </body>
        </body>
      </body>
    </body>
  </worldbody>
  <actuator>
    <motor joint="leg:0 segment:0" gear="100" />
    <motor joint="leg:0 segment:1" gear="100" />
    <motor joint="leg:0 segment:2" gear="100" />
  </actuator>
</mujoco>